Traceback (most recent call last):
  File "E:\dev\wPCC_pipeline\venv\lib\site-packages\jupyter_cache\executors\utils.py", line 64, in single_nb_execution
    **kwargs,
  File "E:\dev\wPCC_pipeline\venv\lib\site-packages\nbclient\client.py", line 1093, in execute
    return NotebookClient(nb=nb, resources=resources, km=km, **kwargs).execute()
  File "E:\dev\wPCC_pipeline\venv\lib\site-packages\nbclient\util.py", line 84, in wrapped
    return just_run(coro(*args, **kwargs))
  File "E:\dev\wPCC_pipeline\venv\lib\site-packages\nbclient\util.py", line 62, in just_run
    return loop.run_until_complete(coro)
  File "C:\Python37-64\lib\asyncio\base_events.py", line 587, in run_until_complete
    return future.result()
  File "E:\dev\wPCC_pipeline\venv\lib\site-packages\nbclient\client.py", line 560, in async_execute
    cell, index, execution_count=self.code_cells_executed + 1
  File "E:\dev\wPCC_pipeline\venv\lib\site-packages\nbclient\client.py", line 854, in async_execute_cell
    self._check_raise_for_error(cell, exec_reply)
  File "E:\dev\wPCC_pipeline\venv\lib\site-packages\nbclient\client.py", line 756, in _check_raise_for_error
    raise CellExecutionError.from_cell_and_msg(cell, exec_reply_content)
nbclient.exceptions.CellExecutionError: An error occurred while executing the following cell:
------------------
# %load imports.py
%load_ext autoreload
%autoreload 2
%reload_kedro
%config Completer.use_jedi = False  ## (To fix autocomplete)

import pandas as pd
from src.models.vmm import ModelSimulator
import matplotlib.pyplot as plt
from src.visualization.plot import track_plots, plot, captive_plot
import kedro
import numpy as np
import os.path
import anyconfig

import matplotlib
matplotlib.rcParams["figure.figsize"] = (15,4)

from myst_nb import glue
from src.symbols import *
import src.symbols as symbols
from src.system_equations import *

from IPython.display import display, Math, Latex, Markdown
from sympy.physics.vector.printing import vpprint, vlatex

from src.parameters import df_parameters
p = df_parameters["symbol"]

# Read configs:
conf_path = os.path.join("../../conf/base/")
runs_globals_path = os.path.join(
    conf_path,
    "runs_globals.yml",
)

runs_globals = anyconfig.load(runs_globals_path)
model_test_ids = runs_globals["model_test_ids"]

join_globals_path = os.path.join(
    conf_path,
    "join_globals.yml",
)

joins = runs_globals["joins"]
join_runs_dict = anyconfig.load(join_globals_path)

globals_path = os.path.join(
    conf_path,
    "globals.yml",
)
global_variables = anyconfig.load(globals_path)



vmm_names = global_variables["vmms"]

vmms = {}
for vmm_name in vmm_names:
    vmms[vmm_name] = catalog.load(vmm_name)

------------------


UsageError: Line magic function `%reload_kedro` not found.

